Workbook

Sheet Master Summary
A1: SL | B1: Batch | C1: Course Status | D1: Student ID | E1: Student Name | F1: Mobile Number | G1: Guardian Number | H1: Present | I1: Absent | J1: Excused | K1: Total Classes Recorded | L1: Attendance %
A2: 1 | B2: MASSIVE 24A | C2: Complete | D2: ='MASSIVE 24A '!C4 -> 155 | E2: ='MASSIVE 24A '!B4 -> MD YEAHIA KHAN ZIHAD | F2: ='MASSIVE 24A '!D4 -> 01732-821850 | G2: ='MASSIVE 24A '!E4 -> 01676-508815 | H2: No attendance sheet | I2: No attendance sheet | J2: No attendance sheet | K2: No attendance sheet | L2: No attendance sheet
A3: 2 | B3: MASSIVE 24A | C3: Complete | D3: ='MASSIVE 24A '!C5 -> 173 | E3: ='MASSIVE 24A '!B5 -> NIYAZ MORSHED | F3: ='MASSIVE 24A '!D5 -> 01854-043818 | G3: ='MASSIVE 24A '!E5 -> 01816-335423 | H3: No attendance sheet | I3: No attendance sheet | J3: No attendance sheet | K3: No attendance sheet | L3: No attendance sheet
A4: 3 | B4: MASSIVE 24A | C4: Complete | D4: ='MASSIVE 24A '!C6 -> 165 | E4: ='MASSIVE 24A '!B6 -> MOINUL HASAN | F4: ='MASSIVE 24A '!D6 -> 01867-072375 | G4: ='MASSIVE 24A '!E6 -> 01816-335423 | H4: No attendance sheet | I4: No attendance sheet | J4: No attendance sheet | K4: No attendance sheet | L4: No attendance sheet
A5: 4 | B5: MASSIVE 24A | C5: Complete | D5: ='MASSIVE 24A '!C7 -> 167 | E5: ='MASSIVE 24A '!B7 -> MD ASIQUJJMAN TAMIM | F5: ='MASSIVE 24A '!D7 -> 01818-093643 | G5: ='MASSIVE 24A '!E7 -> 01711-271062 | H5: No attendance sheet | I5: No attendance sheet | J5: No attendance sheet | K5: No attendance sheet | L5: No attendance sheet
A6: 5 | B6: MASSIVE 24A | C6: Complete | D6: ='MASSIVE 24A '!C8 -> 170 | E6: ='MASSIVE 24A '!B8 -> MEHEDI HASAN | F6: ='MASSIVE 24A '!D8 -> 01628-357219 | G6: ='MASSIVE 24A '!E8 -> 01761-865845 | H6: No attendance sheet | I6: No attendance sheet | J6: No attendance sheet | K6: No attendance sheet | L6: No attendance sheet
A7: 6 | B7: MASSIVE 24A | C7: Complete | D7: ='MASSIVE 24A '!C9 -> 168 | E7: ='MASSIVE 24A '!B9 -> MD ABU ZAFAR | F7: ='MASSIVE 24A '!D9 -> 01326-241930 | G7: ='MASSIVE 24A '!E9 -> 01816-572569 | H7: No attendance sheet | I7: No attendance sheet | J7: No attendance sheet | K7: No attendance sheet | L7: No attendance sheet
A8: 7 | B8: MASSIVE 24A | C8: Complete | D8: ='MASSIVE 24A '!C10 -> 203 | E8: ='MASSIVE 24A '!B10 -> MD ABUL ALIM | F8: ='MASSIVE 24A '!D10 -> 01850-405109 | G8: ='MASSIVE 24A '!E10 -> 01735-956866 | H8: No attendance sheet | I8: No attendance sheet | J8: No attendance sheet | K8: No attendance sheet | L8: No attendance sheet
A9: 8 | B9: MASSIVE 24A | C9: Complete | D9: ='MASSIVE 24A '!C11 -> 232 | E9: ='MASSIVE 24A '!B11 -> MD ZAHADUR RAHMAN | F9: ='MASSIVE 24A '!D11 -> 01937-171494 | G9: ='MASSIVE 24A '!E11 -> 0 | H9: No attendance sheet | I9: No attendance sheet | J9: No attendance sheet | K9: No attendance sheet | L9: No attendance sheet
A10: 9 | B10: MASSIVE 24A | C10: Complete | D10: ='MASSIVE 24A '!C12 -> 154 | E10: ='MASSIVE 24A '!B12 -> MD SAHADAT HOSSAIN | F10: ='MASSIVE 24A '!D12 -> 01401-452420 | G10: ='MASSIVE 24A '!E12 -> 018622-89200 | H10: No attendance sheet | I10: No attendance sheet | J10: No attendance sheet | K10: No attendance sheet | L10: No attendance sheet
A11: 10 | B11: MASSIVE 24A | C11: Complete | D11: ='MASSIVE 24A '!C13 -> 181 | E11: ='MASSIVE 24A '!B13 -> ARMAN HOSSAIN SHEIKH | F11: ='MASSIVE 24A '!D13 -> 01796-589722 | G11: ='MASSIVE 24A '!E13 -> 01315-334552 | H11: No attendance sheet | I11: No attendance sheet | J11: No attendance sheet | K11: No attendance sheet | L11: No attendance sheet
A12: 11 | B12: MASSIVE 24A | C12: Complete | D12: ='MASSIVE 24A '!C14 -> 182 | E12: ='MASSIVE 24A '!B14 -> SIMU HOSSAIN | F12: ='MASSIVE 24A '!D14 -> 01732-805995 | G12: ='MASSIVE 24A '!E14 -> 01732-805995 | H12: No attendance sheet | I12: No attendance sheet | J12: No attendance sheet | K12: No attendance sheet | L12: No attendance sheet
A13: 12 | B13: MASSIVE 24A | C13: Complete | D13: ='MASSIVE 24A '!C15 -> 174 | E13: ='MASSIVE 24A '!B15 -> ARIF JAMAN | F13: ='MASSIVE 24A '!D15 -> 01402-815649 | G13: ='MASSIVE 24A '!E15 -> 01622-993487 | H13: No attendance sheet | I13: No attendance sheet | J13: No attendance sheet | K13: No attendance sheet | L13: No attendance sheet
... A29: 28 | B29: MASSIVE 24A | C29: Complete | D29: ='MASSIVE 24A '!C31 -> 204 | E29: ='MASSIVE 24A '!B31 -> Rifat Foraji | F29: ='MASSIVE 24A '!D31 -> 01779-38885 | G29: ='MASSIVE 24A '!E31 -> 01721-068412 | H29: No attendance sheet | I29: No attendance sheet | J29: No attendance sheet | K29: No attendance sheet | L29: No attendance sheet
A30: 29 | B30: MASSIVE 24B | C30: Complete | D30: ='MASSIVE 24B'!C4 -> 171 | E30: ='MASSIVE 24B'!B4 -> SUVRA MALAKER | F30: ='MASSIVE 24B'!D4 -> 01674-470243 | G30: ='MASSIVE 24B'!E4 -> 01521-216898 | H30: No attendance sheet | I30: No attendance sheet | J30: No attendance sheet | K30: No attendance sheet | L30: No attendance sheet
A31: 30 | B31: MASSIVE 24B | C31: Complete | D31: ='MASSIVE 24B'!C5 -> 156 | E31: ='MASSIVE 24B'!B5 -> MD AFNAN HOSEN ALIF | F31: ='MASSIVE 24B'!D5 -> 01303-844242 | G31: ='MASSIVE 24B'!E5 -> 01303-844242 | H31: No attendance sheet | I31: No attendance sheet | J31: No attendance sheet | K31: No attendance sheet | L31: No attendance sheet
A32: 31 | B32: MASSIVE 24B | C32: Complete | D32: ='MASSIVE 24B'!C6 -> 158 | E32: ='MASSIVE 24B'!B6 -> JAHURA AKTER | F32: ='MASSIVE 24B'!D6 -> 0 | G32: ='MASSIVE 24B'!E6 -> 01720-234626 | H32: No attendance sheet | I32: No attendance sheet | J32: No attendance sheet | K32: No attendance sheet | L32: No attendance sheet
A33: 32 | B33: MASSIVE 24B | C33: Complete | D33: ='MASSIVE 24B'!C7 -> 129 | E33: ='MASSIVE 24B'!B7 -> MD ARIF MIAH | F33: ='MASSIVE 24B'!D7 -> 01619-745810 | G33: ='MASSIVE 24B'!E7 -> 01887-403519 | H33: No attendance sheet | I33: No attendance sheet | J33: No attendance sheet | K33: No attendance sheet | L33: No attendance sheet
A34: 33 | B34: MASSIVE 24B | C34: Complete | D34: ='MASSIVE 24B'!C8 -> 130 | E34: ='MASSIVE 24B'!B8 -> MEHADI HASAN | F34: ='MASSIVE 24B'!D8 -> 01705-062132 | G34: ='MASSIVE 24B'!E8 -> 01571-425749 | H34: No attendance sheet | I34: No attendance sheet | J34: No attendance sheet | K34: No attendance sheet | L34: No attendance sheet
A35: 34 | B35: MASSIVE 24B | C35: Complete | D35: ='MASSIVE 24B'!C9 -> 131 | E35: ='MASSIVE 24B'!B9 -> MD KAMRUL ISLAM ASHIK | F35: ='MASSIVE 24B'!D9 -> 01840-520260 | G35: ='MASSIVE 24B'!E9 -> 01516-789519 | H35: No attendance sheet | I35: No attendance sheet | J35: No attendance sheet | K35: No attendance sheet | L35: No attendance sheet
A36: 35 | B36: MASSIVE 24B | C36: Complete | D36: ='MASSIVE 24B'!C10 -> 133 | E36: ='MASSIVE 24B'!B10 -> MD ALAUDDIN | F36: ='MASSIVE 24B'!D10 -> 01995-072029 | G36: ='MASSIVE 24B'!E10 -> 01886-347582 | H36: No attendance sheet | I36: No attendance sheet | J36: No attendance sheet | K36: No attendance sheet | L36: No attendance sheet
A37: 36 | B37: MASSIVE 24B | C37: Complete | D37: ='MASSIVE 24B'!C11 -> 134 | E37: ='MASSIVE 24B'!B11 -> KAWSER AHAMED | F37: ='MASSIVE 24B'!D11 -> 01887-397509 | G37: ='MASSIVE 24B'!E11 -> 01644-352805 | H37: No attendance sheet | I37: No attendance sheet | J37: No attendance sheet | K37: No attendance sheet | L37: No attendance sheet
A38: 37 | B38: MASSIVE 24B | C38: Complete | D38: ='MASSIVE 24B'!C12 -> 147 | E38: ='MASSIVE 24B'!B12 -> MAHABUB HASAN SHUVO | F38: ='MASSIVE 24B'!D12 -> 01842-115268 | G38: ='MASSIVE 24B'!E12 -> 01720-044163 | H38: No attendance sheet | I38: No attendance sheet | J38: No attendance sheet | K38: No attendance sheet | L38: No attendance sheet
A39: 38 | B39: MASSIVE 24B | C39: Complete | D39: ='MASSIVE 24B'!C13 -> 141 | E39: ='MASSIVE 24B'!B13 -> JANNAT FATEMA | F39: ='MASSIVE 24B'!D13 -> 01762-404885 | G39: ='MASSIVE 24B'!E13 -> 01762-404885 | H39: No attendance sheet | I39: No attendance sheet | J39: No attendance sheet | K39: No attendance sheet | L39: No attendance sheet
A40: 39 | B40: MASSIVE 24B | C40: Complete | D40: ='MASSIVE 24B'!C14 -> 142 | E40: ='MASSIVE 24B'!B14 -> SURAIYA AHMED | F40: ='MASSIVE 24B'!D14 -> 01712-331187 | G40: ='MASSIVE 24B'!E14 -> 0 | H40: No attendance sheet | I40: No attendance sheet | J40: No attendance sheet | K40: No attendance sheet | L40: No attendance sheet
A41: 40 | B41: MASSIVE 24B | C41: Complete | D41: ='MASSIVE 24B'!C15 -> 140 | E41: ='MASSIVE 24B'!B15 -> SHEIKH SEAMUR RAHMAN NIBIR | F41: ='MASSIVE 24B'!D15 -> 01639-566941 | G41: ='MASSIVE 24B'!E15 -> 01301-483707 | H41: No attendance sheet | I41: No attendance sheet | J41: No attendance sheet | K41: No attendance sheet | L41: No attendance sheet
... A61: 60 | B61: MASSIVE 24B | C61: Complete | D61: ='MASSIVE 24B'!C35 -> 108 | E61: ='MASSIVE 24B'!B35 -> HAJERA AKTER | F61: ='MASSIVE 24B'!D35 -> 01879-877425 | G61: ='MASSIVE 24B'!E35 -> 01882-891472 | H61: No attendance sheet | I61: No attendance sheet | J61: No attendance sheet | K61: No attendance sheet | L61: No attendance sheet
A62: 61 | B62: MASSIVE 25A | C62: Complete | D62: ='MASSIVE 25A'!C4 -> 190 | E62: ='MASSIVE 25A'!B4 -> Nazmul Hasan | F62: ='MASSIVE 25A'!D4 -> 1841561838 | G62: ='MASSIVE 25A'!E4 -> 1724761838 | H62: No attendance sheet | I62: No attendance sheet | J62: No attendance sheet | K62: No attendance sheet | L62: No attendance sheet
A63: 62 | B63: MASSIVE 25A | C63: Complete | D63: ='MASSIVE 25A'!C5 -> 193 | E63: ='MASSIVE 25A'!B5 -> Sumaiya Arefin Sumu | F63: ='MASSIVE 25A'!D5 -> 1784883491 | G63: ='MASSIVE 25A'!E5 -> 1711663693 | H63: No attendance sheet | I63: No attendance sheet | J63: No attendance sheet | K63: No attendance sheet | L63: No attendance sheet
A64: 63 | B64: MASSIVE 25A | C64: Complete | D64: ='MASSIVE 25A'!C6 -> 195 | E64: ='MASSIVE 25A'!B6 -> Tanvir Hsosen | F64: ='MASSIVE 25A'!D6 -> 1407713344 | G64: ='MASSIVE 25A'!E6 -> 1742566344 | H64: No attendance sheet | I64: No attendance sheet | J64: No attendance sheet | K64: No attendance sheet | L64: No attendance sheet
A65: 64 | B65: MASSIVE 25A | C65: Complete | D65: ='MASSIVE 25A'!C7 -> 25109 | E65: ='MASSIVE 25A'!B7 -> Golam Rabbi Akash | F65: ='MASSIVE 25A'!D7 -> 1743606008 | G65: ='MASSIVE 25A'!E7 -> 1742566344 | H65: No attendance sheet | I65: No attendance sheet | J65: No attendance sheet | K65: No attendance sheet | L65: No attendance sheet
A66: 65 | B66: MASSIVE 25A | C66: Complete | D66: ='MASSIVE 25A'!C8 -> 197 | E66: ='MASSIVE 25A'!B8 -> Md Miraj | F66: ='MASSIVE 25A'!D8 -> 1611114494 | G66: ='MASSIVE 25A'!E8 -> 1978488787 | H66: No attendance sheet | I66: No attendance sheet | J66: No attendance sheet | K66: No attendance sheet | L66: No attendance sheet
A67: 66 | B67: MASSIVE 25A | C67: Complete | D67: ='MASSIVE 25A'!C9 -> 194 | E67: ='MASSIVE 25A'!B9 -> Nasrin Akter Lima | F67: ='MASSIVE 25A'!D9 -> 1841827218 | G67: ='MASSIVE 25A'!E9 -> 1712727217 | H67: No attendance sheet | I67: No attendance sheet | J67: No attendance sheet | K67: No attendance sheet | L67: No attendance sheet
A68: 67 | B68: MASSIVE 25B | C68: Complete | D68: ='MASSIVE 25B'!C4 -> 214 | E68: ='MASSIVE 25B'!B4 -> Jubaer Abdullah Saad | F68: ='MASSIVE 25B'!D4 -> 1792252125 | G68: ='MASSIVE 25B'!E4 -> 1914197796 | H68: No attendance sheet | I68: No attendance sheet | J68: No attendance sheet | K68: No attendance sheet | L68: No attendance sheet
A69: 68 | B69: MASSIVE 25B | C69: Complete | D69: ='MASSIVE 25B'!C5 -> 213 | E69: ='MASSIVE 25B'!B5 -> Shahriara Abdullah Shihab | F69: ='MASSIVE 25B'!D5 -> 1707764197 | G69: ='MASSIVE 25B'!E5 -> 1914197796 | H69: No attendance sheet | I69: No attendance sheet | J69: No attendance sheet | K69: No attendance sheet | L69: No attendance sheet
A70: 69 | B70: MASSIVE 25B | C70: Complete | D70: ='MASSIVE 25B'!C6 -> 211 | E70: ='MASSIVE 25B'!B6 -> Hasibul Hasan Hasib | F70: ='MASSIVE 25B'!D6 -> 1997735946 | G70: ='MASSIVE 25B'!E6 -> 1719050659 | H70: No attendance sheet | I70: No attendance sheet | J70: No attendance sheet | K70: No attendance sheet | L70: No attendance sheet
A71: 70 | B71: MASSIVE 25B | C71: Complete | D71: ='MASSIVE 25B'!C7 -> 210 | E71: ='MASSIVE 25B'!B7 -> Riyad Khandaker | F71: ='MASSIVE 25B'!D7 -> 1639440531 | G71: ='MASSIVE 25B'!E7 -> 1837458138 | H71: No attendance sheet | I71: No attendance sheet | J71: No attendance sheet | K71: No attendance sheet | L71: No attendance sheet
A72: 71 | B72: MASSIVE 25B | C72: Complete | D72: ='MASSIVE 25B'!C8 -> 208 | E72: ='MASSIVE 25B'!B8 -> Shagor Mondol | F72: ='MASSIVE 25B'!D8 -> 1884338224 | G72: ='MASSIVE 25B'!E8 -> 0 | H72: No attendance sheet | I72: No attendance sheet | J72: No attendance sheet | K72: No attendance sheet | L72: No attendance sheet
A73: 72 | B73: MASSIVE 25B | C73: Complete | D73: ='MASSIVE 25B'!C9 -> 199 | E73: ='MASSIVE 25B'!B9 -> Tamim Visty | F73: ='MASSIVE 25B'!D9 -> 1810514924 | G73: ='MASSIVE 25B'!E9 -> 1408698780 | H73: No attendance sheet | I73: No attendance sheet | J73: No attendance sheet | K73: No attendance sheet | L73: No attendance sheet
A74: 73 | B74: MASSIVE 25B | C74: Complete | D74: ='MASSIVE 25B'!C10 -> 198 | E74: ='MASSIVE 25B'!B10 -> Md. Azizul Hakim | F74: ='MASSIVE 25B'!D10 -> 1772847587 | G74: ='MASSIVE 25B'!E10 -> 1761741406 | H74: No attendance sheet | I74: No attendance sheet | J74: No attendance sheet | K74: No attendance sheet | L74: No attendance sheet
...

Sheet ORGINAL
A1: MASSIVE 25G সকাল ১০টা থেকে ১২টা
A2: Course Duration | F2: Course Status :
A3: SL NO. | B3: Student Name | C3: Student ID | D3: Mobile Number | E3: Guardian Number | F3: Date Of Birth | G3: Guarantor | H3: Relationship With Guarantor | I3: COMMENT
A4: 1
A5: 2
A6: 3
A7: 4
A8: 5
A9: 6
A10: 7
A11: 8
A12: 9
A13: 10
A14: 11
A15: 12
... A20: 17
A21: `18
A22: 19
A23: 20
A24: 21
A25: 22
A26: 23

Sheet Sheet30
A1: STUDENT VISA
A2: SL. | B2: Id No | C2: Name | D2: Number | E2: Class | F2: UPDATE
A3: 1 | B3: 143 | C3: Afroza Akter Ria | D3: 01757-501979 | F3: 46113
A4: 2 | B4: 139 | C4: Rifat Islam Apurbo | D4: 01836-813717 | F4: 46113
A5: 3 | B5: 155 | C5: Md Yeahia Khan Zihad | D5: 01732-821850
A6: 4 | B6: 173 | C6: Niyaz Morshed | D6: 01816-335423 | F6: 46113
A7: 5 | B7: 170 | C7: Mehedi Hasan | D7: 01761-865845 | E7: MASSIVE 25I N4 | F7: 46113
A8: 6 | B8: 203 | C8: Md Abdul Alim | D8: 01735-956866 | E8: MASSIVE 24A | F8: 46113
A9: 7 | B9: 25201 | C9: Hasibul Alom Rapty | D9: 01683-871353 | F9: 46296
A10: 8 | B10: 180 | C10: Jabed Hosain | D10: 01935-827859 | F10: 46113
A11: 9 | B11: 25202 | C11: Mst Nusrat Jahan Neela | D11: 01912-834664
A12: 10 | B12: 185 | C12: Kamruna Akter | D12: 01731-302196
A13: 11 | B13: 184 | C13: Ehsanul Bari | D13: 01957-007394 | F13: 46113
A14: 12 | B14: 205 | C14: Jesan Khan | D14: 01716-025629 | F14: 46113
A15: 13 | B15: 193 | C15: Sumaiya Arefin Sumu | D15: 01784-883491 | F15: 46113
A16: 14 | B16: 211 | C16: Hasibul Hasan Hasib | D16: 01997-735946 | F16: 46114
A17: 15 | B17: 208 | C17: Shagor Mondol | D17: 01884-338224/ 01712-097253
A18: 16 | B18: 220 | C18: Md. Junayed Goni | D18: 01639-141041 | F18: 46296
A19: 17 | B19: 221 | C19: Md. Asadozzaman Sadir | D19: 01614-935456 | E19: MASSIVE 25I N4 | F19: 46113
A20: 18 | B20: 231 | C20: Shikin | D20: 01897-607430 | E20: MASSIVE 24A | F20: 46113
A21: 19 | B21: 229 | C21: Mohammed Riad | D21: 01881-363564 | E21: ONLY FILE PROCESSING | F21: 46114
A22: 20 | B22: 25112 | C22: Md Arif Hossain | E22: MASSIVE 25C
A23: 21 | B23: 25113 | C23: Tahamida Islam | D23: 01992-302780 | E23: MASSIVE 25C | F23: 46114
A24: 22 | B24: 25114 | C24: Sohanur Rahman Sohag | D24: 01956-245865 | E24: MASSIVE 25C | F24: 46296
A25: 23 | B25: 25115 | C25: Minhajul Abedin Sihab | D25: 01310-561280 | E25: MASSIVE 25C | F25: 46113
A26: 24 | B26: 25111 | C26: Md Mahim Chokder | D26: 01735-718862 | E26: ONLY FILE PROCESSING | F26: 46114
A27: 25 | B27: 25130 | C27: Md Omar Faruk | D27: 01311-462754 | E27: MASSIVE 25C | F27: 46113
A28: 26 | B28: 25131 | C28: Mahadi Hasan Fardin | D28: 01622-788915 | E28: MASSIVE 25F | F28: 46204
A29: 27 | B29: 25135 | C29: Md Yousuf | E29: ONLY FILE PROCESSING | F29: 46113
A30: 28 | B30: 25139 | C30: Shak Md Rahin | D30: 01720-385466 | E30: MASSIVE 25C
A31: 29 | B31: 25140 | C31: Mahinur Ahmed | D31: 01903-557838 | E31: MASSIVE 25C | F31: 46113
A32: 30 | B32: 25142 | C32: Md Solaiman Sheikh | D32: 01818-209125 | E32: MASSIVE 25I N4 | F32: 46113
A33: 31 | B33: 25146 | C33: Sanjidur Rahman | D33: 0187-7681497 | E33: MASSIVE 25H
A34: 32 | B34: 25149 | C34: Tabassum Jidni Shoha | D34: 01825-401806 | E34: MASSIVE 25C
A35: 33 | B35: 25153 | C35: Al Jubair | D35: 01873-652079 | E35: MASSIVE 25G | F35: 46296
A36: 34 | B36: 25155 | C36: Tonmoy Mallik | D36: 01856-666518 | E36: MASSIVE 25C | F36: 46113
A37: 35 | B37: 25157 | C37: Pronob Kumar Das | D37: 01792-160685 | E37: MASSIVE 25G
A38: 36 | B38: 25159 | C38: Md Anamul Hasan Sabbir | D38: 01828-023752 | E38: MASSIVE 25G
A39: 37 | B39: 25158 | C39: Yeamin Senriabat | D39: 01828-960337 | E39: MASSIVE 25G
A40: 38 | B40: 25161 | C40: Kawshar Hasan Sumit | D40: 01300-774779 | E40: MASSIVE 25H
...

Sheet Student list
A1: cp
A2: DATE | B2: NAME | C2: NUMBER | D2: REF.
B3: SHAMIM | C3: 01324-724989 | D3: SONDHA KALIN
B4: SALEHA AKTER SIKHA | C4: 01776-203072 | D4: SONDHA KALIN
A6: 45962 | B6: MEHEDI HASAN | C6: 01834-306998 | D6: NEW BATCH
A7: 45964 | B7: Omit Mollik | C7: 01789-774090 | D7: Tonmoy Mollik
A8: 45964 | B8: Shahnewaj | C8: 01825-136954 | D8: Tonmoy Mollik
A10: 45976 | B10: SOJIB | C10: 01319-347720
A11: 45979 | B11: maksud alom | C11: 01992-932246
A12: 45978 | B12: Rahat | C12: 01793-688129 | D12: jan mase
A13: 45983 | B13: Sumaiya | D13: sagor vai
A14: 45984 | B14: sayem sarker | C14: 01755-939460 | D14: RAKIB | E14: N4
A16: 45990 | B16: ANISUR JAMAN | C16: 01894-804951
A17: 45990 | B17: MD ABDUL JABBOR | C17: 01957-969126
B19: suma paul | C19: 01622-993120 | D19: new batch
A20: 46002 | B20: Ridul | C20: 01815-471090 | D20: jabed | E20: 3
B21: SHAKIL VAI | C21: 01970-016544
B22: SHAKIL VAI | C22: 01608-068552
A24: 46014 | B24: MD OPU | C24: 01974-555483 | D24: COMPUTER DOKAN
A25: 46014 | B25: DIN MOHAMOD | C25: 01915-155555 | D25: COMPUTER DOKAN
B26: SHAKIL VAI | C26: 01609-728911
B27: SHAKIL VAI | C27: 014049-38126
B28: SHAKIL VAI | C28: 016400-46781
B29: SHAKIL VAI | C29: 01714-394866
B30: SHAKIL VAI | C30: 016080-68552
B34: SABBIR AHMED | C34: 01630-107374
B35: MEHRAB | C35: 01768-211968 | D35: rakib
B36: MD AWLAD HOSSAIN | C36: 01799-300800
B37: TARIF | C37: 01760-127998
B38: SUSMITA AKTER EVA | C38: 01991-464360
B39: OMIT | C39: 01963-605906
B40: RASEDUL ISLAM | C40: 01821-665275
A42: 25/02/2026 | B42: MD SELIM | C42: 01796-409850
A43: 25/02/2026 | B43: MD FERDOS | C43: 01586-090181
A44: 28/02/2027 | B44: jahid | C44: 01612-061037 | D44: N4
A45: 28/02/2027 | B45: puspa | C45: 01955-104800
A46: 28/02/2027 | B46: samid | C46: 01873-181302
A47: 28/02/2027 | B47: sagor | C47: 01790-375455 | D47: N4
A49: 30/02/2027 | B49: EMON | C49: 01754-634951 | D49: N5 | E49: RAKIB

Sheet MASSIVE 24A 
A1: MASSIVE 24A
A2: Course Duration: | F2: Course Status : Complete
A3: SL NO. | B3: Student Name | C3: Student ID | D3: Mobile Number | E3: Guardian Number | F3: Date Of Birth | G3: Guarantor | H3: Relationship With Guarantor | I3: COMMENT
A4: 1 | B4: MD YEAHIA KHAN ZIHAD | C4: 155 | D4: 01732-821850 | E4: 01676-508815 | F4: 27/08/2005
A5: 2 | B5: NIYAZ MORSHED | C5: 173 | D5: 01854-043818 | E5: 01816-335423 | F5: 31/08/2003
A6: 3 | B6: MOINUL HASAN | C6: 165 | D6: 01867-072375 | E6: 01816-335423 | F6: 31/08/2003
A7: 4 | B7: MD ASIQUJJMAN TAMIM | C7: 167 | D7: 01818-093643 | E7: 01711-271062 | F7: 20/02/2003
A8: 5 | B8: MEHEDI HASAN | C8: 170 | D8: 01628-357219 | E8: 01761-865845 | F8: 14/08/2005
A9: 6 | B9: MD ABU ZAFAR | C9: 168 | D9: 01326-241930 | E9: 01816-572569 | F9: 33604
A10: 7 | B10: MD ABUL ALIM | C10: 203 | D10: 01850-405109 | E10: 01735-956866 | F10: 38450
A11: 8 | B11: MD ZAHADUR RAHMAN | C11: 232 | D11: 01937-171494 | F11: 16/12/1982
A12: 9 | B12: MD SAHADAT HOSSAIN | C12: 154 | D12: 01401-452420 | E12: 018622-89200 | F12: 15/06/2005
A13: 10 | B13: ARMAN HOSSAIN SHEIKH | C13: 181 | D13: 01796-589722 | E13: 01315-334552 | F13: 20/12/2004
A14: 11 | B14: SIMU HOSSAIN | C14: 182 | D14: 01732-805995 | E14: 01732-805995 | F14: 17/07/2003
A15: 12 | B15: ARIF JAMAN | C15: 174 | D15: 01402-815649 | E15: 01622-993487 | F15: 25/12/2002
A16: 13 | B16: HASIBUL ALOM RAPTY | C16: N/A | D16: 01990-290405 | E16: 01683-871353 | F16: 38751
A17: 14 | B17: KISHARA KIBRIA RIYA | C17: 202 | D17: 01312-625945 | E17: 01913-419496 | F17: 22/09/2003
A18: 15 | B18: HABIBUL SHIMANTO | C18: 172 | D18: 01860-020671 | E18: 01628-808591 | F18: 37748
A19: 16 | B19: FARHAN KHAN SUVO | C19: 169 | D19: 01916-927676 | E19: 01758-100992 | F19: 33641
A20: 17 | B20: JABED HOSAIN | C20: 180 | D20: 01815-682829 | E20: 01935-827859 | F20: 37233
A21: 18 | B21: MST NUSRAT JAHAN NEELA | C21: n/a | D21: 01987-031668 | E21: 01912-834664 | F21: 37593
A22: 19 | B22: MD EBRAHIM HASAN | C22: 183 | D22: 01608-876825 | E22: 01608-876825
A23: 20 | B23: MD SHAHJALAL | C23: 189 | D23: 01883-543069 | F23: 17/10/2005
A24: 21 | B24: KAMRUNA AKTER | C24: 185 | D24: 01961-686060 | E24: 01731-302196 | F24: 25/02/2003
A25: 22 | B25: RIDOY | C25: N/A | E25: 01731-302196 | F25: 39908
A26: 23 | B26: EHSANUL BARI | C26: 184 | D26: 01921-458135 | E26: 01957-007394 | F26: 38355
A27: 24 | B27: SUNJIDA NAHAR SHUMIYA | C27: 186 | D27: 01730-845444 | E27: 01730-845444 | F27: 20/06/1999
A28: 25 | B28: MD AHANAF ADIL | C28: 179 | D28: 01978-349007 | F28: 28/02/2007
A29: 26 | B29: JESAN KHAN | C29: 205 | D29: 01764-299473 | E29: 01716-025629 | F29: 24/09/2006
A30: 27 | B30: JAMAL MIAH | C30: 161 | D30: 01705-287924 | E30: 01862-274133 | F30: 28/05/2003
A31: 28 | B31: Rifat Foraji | C31: 204 | D31: 01779-38885 | E31: 01721-068412 | F31: 06/09/2002

Sheet MASSIVE  24B
A1: MASSIVE 24B
A2: Course Duration | F2: Course Status : Complete
A3: SL NO. | B3: Student Name | C3: STUDENT ID | D3: Mobile Number | E3: Guardian Number | F3: Date Of Birth | G3: Guarantor | H3: Relationship With Guarantor | I3: COMMENT
A4: 1 | B4: SUVRA MALAKER | C4: 171 | D4: 01674-470243 | E4: 01521-216898 | F4: 18/09/1990
A5: 2 | B5: MD AFNAN HOSEN ALIF | C5: 156 | D5: 01303-844242 | E5: 01303-844242 | F5: 21/01/2003
A6: 3 | B6: JAHURA AKTER | C6: 158 | E6: 01720-234626 | F6: 15/01/2007
A7: 4 | B7: MD ARIF MIAH | C7: 129 | D7: 01619-745810 | E7: 01887-403519 | F7: 31/12/2002
A8: 5 | B8: MEHADI HASAN | C8: 130 | D8: 01705-062132 | E8: 01571-425749 | F8: 36561
A9: 6 | B9: MD KAMRUL ISLAM ASHIK | C9: 131 | D9: 01840-520260 | E9: 01516-789519 | F9: 15/04/1996
A10: 7 | B10: MD ALAUDDIN | C10: 133 | D10: 01995-072029 | E10: 01886-347582 | F10: 17/05/2002
A11: 8 | B11: KAWSER AHAMED | C11: 134 | D11: 01887-397509 | E11: 01644-352805 | F11: 14/12/2003
A12: 9 | B12: MAHABUB HASAN SHUVO | C12: 147 | D12: 01842-115268 | E12: 01720-044163 | F12: 27/11/204
A13: 10 | B13: JANNAT FATEMA | C13: 141 | D13: 01762-404885 | E13: 01762-404885 | F13: 26/07/1997
A14: 11 | B14: SURAIYA AHMED | C14: 142 | D14: 01712-331187 | F14: 17/09/1996
A15: 12 | B15: SHEIKH SEAMUR RAHMAN NIBIR | C15: 140 | D15: 01639-566941 | E15: 01301-483707 | F15: 37419
A16: 13 | B16: RIFAT ISLAM APURBO | C16: 139 | D16: 01836-813717 | E16: 01945-199316 | F16: 37357
A17: 14 | B17: AKTER HOSSAIN | C17: 138 | D17: 01568-477334 | E17: 01568-477339 | F17: 39663
A18: 15 | B18: ROKEYA HOSSAIN | C18: 144 | D18: 01994-685177 | E18: 01710-149544 | F18: 36102
A19: 16 | B19: JANNATUL FERDOUS PAYEL | C19: 135 | D19: 01537-309614 | E19: 01712-988967 | F19: 19/02/2004
A20: 17 | B20: RAHAT HOSASIN | C20: 149 | D20: 01701-023059 | E20: 01712-643903 | F20: 24/07/1998
A21: 18 | B21: SURMA AKTER | C21: 137 | D21: 01994-897008 | E21: 01914-020262 | F21: 37258
A22: 19 | B22: MD MAHBUBUR RAHMAN RIFAT | C22: 124 | D22: 01762-529307 | F22: 24/01/2002
A23: 20 | B23: ISMAIL | C23: 132 | D23: 01810-864000 | E23: 01734-452122 | F23: 36526
A24: 21 | B24: MDD FAISAL | C24: 126 | D24: 01683-243468 | F24: 26/10/1999
A25: 22 | B25: RAYSUL AHMED BAPON | C25: 145 | D25: 01812-696836 | E25: 01795-186061 | F25: 29/08/2006
A26: 23 | B26: MD RAYHAN | C26: 151 | D26: 01815-256701 | E26: 01924-936245 | F26: 25/12/1999
A27: 24 | B27: SAMSUN NAHAR TAMIM | C27: 148 | D27: 01580-850198 | E27: 01963-088014 | F27: 36199
A28: 25 | B28: MD ZUBAYER AHMED | C28: 152 | D28: 01639-145662 | E28: 01711-694854 | F28: 36862
A29: 26 | B29: RUBEL | C29: 152 | D29: 01866-105368 | E29: 01986-90738 | F29: 34003
A30: 27 | B30: MD SHUAYEEB HOSSAIN | C30: 118 | D30: 01787-401109 | E30: 01749-504389 | F30: 38322
A31: 28 | B31: MD MORSALIN | C31: 117 | D31: 01625-266066 | E31: 01911-331538 | F31: 23/12/2003
A32: 29 | B32: FAHMIDA SUBNAM PRITY | C32: 119 | D32: 01614-415012 | F32: 25/05/2005
A33: 30 | B33: MD ADNAN AHMED | C33: 120 | D33: 01885-576261 | E33: 01718-203491 | F33: 37322
A34: 31 | B34: PRIYA AKTER MOU | C34: 109 | D34: 01676-627798 | E34: 01689-075790 | F34: 35613
A35: 32 | B35: HAJERA AKTER | C35: 108 | D35: 01879-877425 | E35: 01882-891472 | F35: 33271

Sheet MASSIVE  25A
A1: MASSIVE 25A
A2: Course Duration: | F2: Course Status : Complete
A3: SL NO. | B3: Student Name | C3: STUDENT ID | D3: Mobile Number | E3: Guardian Number | F3: Date Of Birth | G3: Guarantor | H3: Relationship With Guarantor | I3: COMMENT
A4: 1 | B4: Nazmul Hasan | C4: 190 | D4: 1841561838 | E4: 1724761838 | F4: 38232
A5: 2 | B5: Sumaiya Arefin Sumu | C5: 193 | D5: 1784883491 | E5: 1711663693 | F5: 38477
A6: 3 | B6: Tanvir Hsosen | C6: 195 | D6: 1407713344 | E6: 1742566344 | F6: 38170
A7: 4 | B7: Golam Rabbi Akash | C7: 25109 | D7: 1743606008 | E7: 1742566344 | F7: 27/09/1999
A8: 5 | B8: Md Miraj | C8: 197 | D8: 1611114494 | E8: 1978488787 | F8: 35920
A9: 6 | B9: Nasrin Akter Lima | C9: 194 | D9: 1841827218 | E9: 1712727217 | F9: 38332

Sheet MASSIVE 25B
A1: MASSIVE 25B
A2: Course Duration: | F2: Course Status : Complete
A3: SL NO. | B3: Student Name | C3: STUDENT ID | D3: Mobile Number | E3: Guardian Number | F3: Date Of Birth | G3: Guarantor | H3: Relationship With Guarantor | I3: COMMENT
A4: 1 | B4: Jubaer Abdullah Saad | C4: 214 | D4: 1792252125 | E4: 1914197796 | F4: 22/09/1997
A5: 2 | B5: Shahriara Abdullah Shihab | C5: 213 | D5: 1707764197 | E5: 1914197796 | F5: 24/04/1994
A6: 3 | B6: Hasibul Hasan Hasib | C6: 211 | D6: 1997735946 | E6: 1719050659 | F6: 31/12/2004
A7: 4 | B7: Riyad Khandaker | C7: 210 | D7: 1639440531 | E7: 1837458138 | F7: 37447
A8: 5 | B8: Shagor Mondol | C8: 208 | D8: 1884338224 | F8: 14/08/2004
A9: 6 | B9: Tamim Visty | C9: 199 | D9: 1810514924 | E9: 1408698780 | F9: 31/12/2005
A10: 7 | B10: Md. Azizul Hakim | C10: 198 | D10: 1772847587 | E10: 1761741406 | F10: 25/11/1999
A11: 8 | B11: Abdullah | C11: 226 | D11: 1893797917 | E11: 1793797917 | F11: 37623

Sheet MASSIVE 25C
A1: Massive 25C দুপুর 12:20 থেকে 2:20 (শনি- সোম- বুধ)
A2: Course Duration: 1 May - Oct 30 | F2: Course Status : Complete
A3: SL NO. | B3: Student Name | C3: Student ID | D3: Mobile Number | E3: Guardian Number | F3: Date Of Birth | G3: Guarantor | H3: Relationship With Guarantor | I3: COMMENT
A4: 1 | B4: Md Zehadur Rahman | C4: 25103 | D4: 01676-099009 | E4: 01735-120196 | F4: 31783
A5: 2 | B5: Md.Yeasin | C5: 25106 | D5: 01874-783398 | E5: 0130-4366941 | F5: 35704
A6: 3 | B6: Tahamida Islam | C6: 25113 | D6: 01992-302780 | E6: 01715-711748 | F6: 17/05/2003
A7: 4 | B7: Sohanur Rahman Sohag | C7: 25114 | D7: 01571-028361 | E7: 01874-310361 | F7: 21/10/2000
A8: 5 | B8: Minhajul Abedin Sihab | C8: 25115 | D8: 01310-561280 | E8: 01720-677381 | F8: 21/01/2003
A9: 6 | B9: Afroza Akter Ria | C9: 143 | D9: 01757-501979 | E9: 01711-248541 | F9: 28/12/2003
A10: 7 | B10: Mahinur Ahmed | C10: 25140 | D10: 01903-557838 | E10: 01755-593815 | F10: 38931
A11: 8 | B11: Tabassum Jidni Shoha | D11: 01825-401806 | E11: 01825-340824 | F11: 30/03/2009
A12: 9 | B12: Faeria Akter Eva | C12: 25116 | D12: 01860-972133 | E12: 01857-308825 | F12: 29/09/2001
A13: 10 | B13: Tonmoy Mollik | C13: 25155 | D13: 01856-666518 | F13: 25/12/2001
A14: 11 | B14: Md Omar Faruk | C14: 25130 | D14: 01311-462754 | F14: 26/01/2004
A15: 12 | B15: Hasibul Hasan Hasib | C15: 211 | D15: 01997-735946 | E15: 01719-050659 | F15: 31/12/2004
A16: 13 | B16: Niyaz Morshed | C16: 173 | D16: 01854-043818 | E16: 01816-335423 | F16: 31/08/2003
A17: 14 | B17: Yousuf
A18: 15 | B18: Riad
A19: 16 | B19: Jarin Moni | C19: 25110 | D19: 01792-480988 | E19: 01777-755327 | F19: 37932
A20: 17 | B20: Zihad
A21: 18 | B21: Sumu
A22: 19 | B22: Chauty Akter | C22: 25104 | D22: 01940-299971 | E22: 01937-077291 | F22: 36652
A23: 20 | B23: Jony Jon Rozario | C23: 25105 | D23: 01752-877522 | E23: 01941-308726 | F23: 29439
A24: 21 | B24: Md Alamin Islam | C24: 25107 | D24: 01932-784978 | F24: 35708
A25: 22 | B25: Md Arif Hossain | C25: 25112 | E25: 01906-066894 | F25: 14/01/2003
A26: 23 | B26: Shak Md Rahin | C26: 25139 | D26: 01720-385466 | E26: 01944-436802 | F26: 26/05/2003
A27: 24 | B27: Md Arafat | C27: 25108 | D27: 01642-584573 | E27: 01689-001606 | F27: 39302
A28: 25 | B28: Anamul Haque Anan | C28: 25101 | D28: 01930-046355 | E28: 01922-093346 | F28: 19/05/1999
A29: 26 | B29: Md Ali Hasan | C29: 25102 | D29: 01997-644347 | E29: 01638-622424 | F29: 38693

Sheet MASSIVE 25F সন্ধ্যাকালীন 
A1: MASSIVE 25F সকাল ১০টা থেকে ১২টা (শনি- সোম- বুধ)
A2: Course Duration: 5 JULY 25 - 31 DEC 25 | F2: Course Status : Complete
A3: SL NO. | B3: Student Name | C3: Student ID | D3: Mobile Number | E3: Guardian Number | F3: Date Of Birth | G3: BLOOD GROUP | H3: Relationship With Guarantor | I3: COMMENT
A4: 1 | B4: RAYHAN KHAN | C4: 25127 | D4: 01973-679741 | E4: 01758-490722 | F4: 38474
A5: 2 | B5: MD SIHAB | C5: 25129 | D5: 01316-316822 | E5: 01724-818179 | F5: 403382 | G5: A+
A6: 3 | B6: MAHADI HASAN FARDIN | C6: 25131 | D6: 01622-788915 | E6: 01622-788915 | F6: 24/7/2006 | G6: O+
A7: 4 | B7: MD MAMUN HOSSAIN | C7: 25132 | D7: 01912-863688 | F7: 24/08/1989 | G7: O+
A8: 5 | B8: RAYHAN HOSSAIN | C8: 25133 | D8: 01840-504083 | F8: 35859 | G8: O+
A9: 6 | B9: MD TOPIBUL RAHMAN | C9: 25134 | D9: 01329-521365 | E9: 01329-521365 | F9: 17/07/1995 | G9: O+
A10: 7 | B10: SOJOL CONDRO DAS | C10: 25138 | D10: 016411-45453
A11: 8 | B11: MD MAHABUB ELAHI | C11: 217 | D11: 01301-696712 | E11: 01715-302880 | F11: 13/08/1998
A12: 9 | B12: HOSSAIN ALI | C12: 25141 | D12: 01673-958244 | F12: 33271 | G12: A+
A13: 10 | B13: MD MIRAZ KHAN | C13: 25150 | D13: 01623-326052 | F13: 13/03/2003 | G13: O+
A14: 11 | B14: RIFAT HOSSAIN | C14: 25194 | D14: 01518-405331 | E14: 01718-707710 | F14: 37016 | G14: A+
A15: 12 | B15: MD MIRAJ | C15: 25160 | D15: 01788-999180 | E15: 01973-899180 | F15: 37912
A16: 13 | B16: SULTAN AHMED | C16: 25177 | D16: 01918-692172 | G16: O+
A17: 14 | B17: ISHAQUE JAHAN SOIKAT | C17: 25185 | D17: 01629-802488 | E17: 01830-938388 | F17: 36525 | G17: B+

Sheet MASSIVE  25D
A1: Massive 25D (রবি, মঙ্গল, বৃহস্পতি :সকাল 10 টা থেকে 12টা)
A2: Course Duration: | F2: Course Status : Complete
A3: SL NO. | B3: Student Name | C3: Student ID | D3: Mobile Number | E3: Guardian Number | F3: Date Of Birth | G3: Guarantor | H3: Relationship With Guarantor | I3: COMMENT
A4: 1 | B4: MD.ELIAS AKBOR | C4: 219 | D4: 01911-682069 | E4: 1676201013 | F4: 13/06/1987
A5: 2 | B5: ABIR MAHAMUD | C5: 218 | D5: 01767-452555 | E5: 1767452555
A6: 3 | B6: MD.JUNAYED GONII | C6: 220 | D6: 1639141041 | F6: 15/04/2000
A7: 4 | B7: MD. ASHIK | C7: 224 | D7: 1795533444 | F7: 23/3/1999
A8: 5 | B8: MD.ASADOZZAMAN SADIR | C8: 221 | D8: 1614935456 | E8: 1765834473 | F8: 39393
A9: 6 | B9: NAHID | C9: 222 | D9: 1906959935 | F9: 14/04/1997
A10: 7 | B10: MD BADRUL ALOM SORON | C10: 225 | D10: 1681232525 | F10: 22/11/1995
A11: 8 | B11: LAMIA AKTER MIM | C11: 235 | D11: 01979-109557 | F11: 17/10/2004
A12: 9 | B12: RIFAT HASAN | C12: 230 | D12: 01537-552123 | E12: 01540-781588 | F12: 38819
A13: 10 | B13: MD.IKHTIYAR HOSEN | C13: 223 | D13: 01609-731308 | F13: 36623

Sheet MASSIVE 25E
A1: Massive 24E দুপুর 12:20 থেকে 2:20 (রবি, মঙ্গল, বৃহস্পতি)
A2: Course Duration: 20 JUNE - 20 DEC 2025 | F2: Course Status : Complete
A3: SL NO. | B3: Student Name | C3: Student ID | D3: Mobile Number | E3: Guardian Number | F3: Date Of Birth | G3: blood group | H3: Guarantor | I3: Relationship With Guarantor | J3: COMMENT
A4: 1 | B4: MD MUFIDUL ISLAM NILOY | C4: 25117 | D4: 01886-320981 | E4: 01681-010533 | F4: 23/12/1999 | G4: A+
A5: 2 | B5: MD MONTASIR RAHMAN | C5: 25118 | D5: 01828-976616 | E5: 01759-129011 | F5: 30/11/2000 | G5: B+
A6: 3 | B6: RIFAT HASAN | C6: 230 | D6: 01537-552123 | E6: 01540-781588 | F6: 38819 | G6: B+
A7: 4 | B7: ANIKA DEWAN | C7: 25120 | D7: 01846-117102 | E7: 01301-054934 | F7: 37441 | G7: B+
A8: 5 | B8: MD MAHADI HASAN | C8: 0 | D8: 01533-465601 | F8: 19/2/2007 | G8: B+
A9: 6 | B9: HASAN Cokder | C9: 25125 | D9: 01622-140141 | E9: 01877-811672 | F9: 28/09/1993
A10: 7 | B10: EIFTI AHMED | C10: 25119 | D10: 01875-318465 | E10: 01868-531499 | F10: 15/11/2000
A11: 8 | B11: MD SHARIR HOSSEN | D11: 01643-711825 | E11: 01714-451783 | F11: 36526
A12: 9 | B12: AMINUL ISLAM JISUN | C12: 25126 | D12: 01758-034945 | E12: 0171954-0296 | F12: 38475
A13: 10 | B13: KOUSIK MITRA | C13: 25128 | D13: 0130-5498009 | E13: 01712-741310 | F13: 38904
A14: 11 | B14: ISTIAK AHMED | C14: 25121 | D14: 01915-151185 | F14: 20/12/2009
A15: 12 | B15: MD MURAD HASAN | C15: 25122 | D15: 01772-320036 | E15: 01929-082894 | F15: 39814
A16: 13 | B16: BM SAAMIR | C16: 25123 | D16: 01782-220275 | E16: 01930-254509 | F16: 40391

Sheet MASSIVE 25G
A1: MASSIVE 25G সকাল ১০টা থেকে ১২টা (শনি- সোম- বুধ)
A2: Course Duration: (27 JULY 2025 - 30 JAN 2026) | H2: Course Status : Complete
A3: SL NO. | B3: BOOK | C3: Student Name | D3: Student ID | E3: Mobile Number | F3: Guardian Number | G3: BLOOD GROUP | H3: Date Of Birth | I3: Guarantor | J3: Relationship with Guarantor | K3: Comment
A4: 1 | B4: OK | C4: MD NAIM KHAN | D4: 25148 | E4: 01629-787994 | F4: 01829-268803 | H4: 18/10/2001
A5: 2 | B5: OK | C5: MD TOUFIK AHMED | D5: 25147 | E5: 01339-633559 | F5: 01675-551262 | G5: AB+ | H5: 26/09/2004
A6: 3 | B6: OK | C6: AL SHAHRIA | D6: 25145 | E6: 01560-015620 | F6: 01745-394026 | G6: O+ | H6: 31/05/2005 | I6: 200 taka
A7: 4 | B7: OK | C7: RASEDUL ISLAM TUSHAR | D7: 25144 | E7: 01798-048367 | F7: 01789-262371 | G7: A- | H7: 21/12/1993
A8: 5 | B8: OK | C8: MD MARUF HOSSAIN SIAM | D8: 25137 | E8: 01984-348666 | F8: 01581-227286 | G8: A+ | H8: 14/04/2001 | I8: 200 taka
A9: 6 | B9: OK | C9: AL JUBAIR | D9: 25153 | E9: 01873-652079 | F9: 01823-417527 | G9: O+ | H9: 37408 | I9: 200 taka
A10: 7 | B10: OK | C10: MD.SADDAM HOSSAIN | D10: 25152 | E10: 01734-812609 | F10: 01855-340041 | G10: A+ | H10: 37622 | I10: 200 taka
A11: 8 | B11: OK | C11: SHANTO MOLLIK | D11: 25154 | E11: 01872-316793 | G11: O+ | H11: 36654
A12: 9 | B12: OK | C12: MUSFIQUR MAHMUD | D12: 25162 | E12: 01788-444277 | F12: 01818-459512 | G12: AB+ | H12: 39727
A13: 10 | B13: OK | C13: SIAM DEWAN | D13: 25156 | E13: 01866-449803 | H13: 26/08/2007 | I13: 200 taka
A14: 11 | B14: OK | C14: ANAMUL HASAN SABBIR | D14: 25159 | E14: 01828-023752 | F14: 01843-168007 | G14: O+ | H14: 25/04/2005 | I14: 200 taka
A15: 12 | B15: OK | C15: PRONOB KUMAR DAS | D15: 25157 | E15: 01951-300381 | F15: 01792-160685 | H15: 16/02/2001
A16: 13 | B16: OK | C16: SAMINUL ISLAM SHIMUL | D16: 25195 | E16: 01739-508577 | F16: 01879-348008 | G16: B+ | H16: 25/07/2006 | I16: 200 taka
A17: 14 | B17: OK | C17: RAYHAN MIAH | D17: 25184 | E17: 01568-531847 | F17: 01581-860242 | G17: A+ | H17: 37899 | I17: 200 taka
A18: 15 | B18: OK | C18: YEAMIN SEHRIABAT | D18: 25158 | E18: 01828-960337 | F18: 96598523956 | G18: A+ | H18: 37987
A19: 16 | B19: OK | C19: MD MUFIDUL ISLAM NILOY | D19: 25117 | E19: 01886-320981 | F19: 01681-010533 | G19: B+ | H19: 23/12/1999
A20: 17 | B20: OK | C20: MD MONTASIR RAHMAN | D20: 25118 | E20: 01828-976616 | F20: 01759-129011 | G20: B+ | H20: 30/11/2000
A21: 18 | B21: OK | C21: RIFAT HASAN | D21: 230 | E21: 01537-552123 | F21: 01540-781588 | G21: B+ | H21: 38819
A22: 19 | B22: OK | C22: ANIKA DEWAN | D22: 25120 | E22: 01846-117102 | F22: 01301-054934 | G22: B+ | H22: 37441
A23: 20 | B23: OK | C23: MD MAHADI HASAN | D23: 0 | E23: 01533-465601 | H23: 19/2/2007
A24: 21 | B24: OK | C24: MUNNI AKTER | D24: 25151 | E24: 01904-678823 | F24: 01999-952793 | H24: 20/01/2000

Sheet MASSIVE 25H
A1: MASSIVE 25H বিকাল ৩টা থেকে ৫টা (শনি- সোম- বুধ)
A2: Course Duration: (20 AUG 2025 - 31 FEB 2026) | G2: Course Status : Complete
A3: SL NO. | B3: BOOK | C3: Student Name | D3: Student ID | E3: Mobile Number | F3: Guardian Number | G3: Blood Group | H3: Date Of Birth | I3: Guarantor | J3: Relationship with Guarantor | K3: Comment
A4: 1 | C4: KAWSHAR HASAN SUMIT | D4: 25161 | E4: 01300-774779 | F4: 01778-226707 | G4: B+ | H4: 24/04/2004
A5: 2 | C5: MD KAWSER HOSSAIN | D5: 25163 | E5: 01766-278131 | F5: 01763-711911 | G5: A+ | H5: 37744
A6: 3 | C6: ARAF SIMANTO MRIDUL | D6: 25164 | E6: 01811-441558 | F6: 01725-775775 | G6: O+ | H6: 38847
A7: 4 | C7: SHARIMIN NAHAR | D7: 25165 | E7: 01745-729831 | F7: 01711-782996 | G7: B+ | H7: 34828
A8: 5 | C8: MD ZAHIDUL ISLAM | D8: 25166 | E8: 01790-743935 | F8: 01711-474921 | G8: O+ | H8: 16/08/2000
A9: 6 | C9: SADIA ISLAM MIM | D9: 25169 | E9: 01300-774575 | F9: 01920-945892 | G9: A+ | H9: 36164
A10: 7 | C10: MD NAJMUS SAKIB | D10: 25170 | E10: 01627-912464 | F10: 01712-605976 | G10: AB+ | H10: 16/11/1999
A11: 8 | C11: MD JUBAER HOSSAIN | D11: 25171 | E11: 01978-705578 | F11: 01715-050334 | G11: A+ | H11: 39060
A12: 9 | C12: MD MIDUL ISLAM | D12: 25172 | E12: 01782-486851 | F12: 01728-161650 | G12: A+ | H12: 36872
A13: 10 | C13: NUSRAT JAHAN | D13: 25173 | E13: 01623-874454 | F13: 01614-937695 | G13: B+ | H13: 28/09/2007
A14: 11 | C14: SANJIDUR RAHMAN | D14: 25146 | E14: 01877-681497 | F14: 01923-435458 | G14: O+ | H14: 39237
A15: 12 | C15: BILLAL HOSSAIN SHUVO | D15: 25143 | E15: 01684-018734 | F15: 01817-113913 | H15: 24/10/1994
A16: 13 | C16: ABDULLAH SARKER OVI | D16: 25175 | E16: 01939-988433 | F16: 01827-565646 | G16: B+ | H16: 24/06/2006
A17: 14 | C17: ABDUR RAHMAN | D17: 25176 | E17: 01977-719584 | G17: 0+ | H17: 13/11/2007
A18: 15 | C18: HASIBUL ALOM RAPTY | D18: 25182 | E18: 01992-090405 | F18: 01606-515053 | G18: A+ | H18: 38751
A19: 16 | C19: NABIL AHAMED | D19: 25124 | E19: 01797-459607 | F19: 01712-254957 | G19: o+ | H19: 30/11/2007
A20: 17 | C20: MD MOHIBULLAH RIYAD | D20: 25167 | E20: 01798-837178 | F20: 01711-474921 | G20: B+ | H20: 37110
A21: 18 | C21: ISMAIL HOSSAIN RAFIN | D21: 25168 | E21: 01977-435967 | F21: 01717-435969 | H21: 15/12/2008
A22: 19 | C22: MD ALAMIN | D22: 25174 | E22: 01911-603824 | F22: 01712-063936 | G22: O+ | H22: 35065
A23: 20 | C23: MD PARVEJ | E23: 01893-765596 | G23: O+ | H23: 37980 | I23: JUBAYER VAI

Sheet MASSIVE 25J
A1: MASSIVE 25J সকাল ১০টা থেকে ১২টা (রবি, মঙ্গল, বৃহস্পতি)
A2: Course Duration: 14/09/25- 14/03/26 | G2: Course Status : COMPLETE
A3: SL NO. | B3: Student Name | C3: BOOK | D3: Student ID | E3: Mobile Number | F3: Guardian Number | G3: Date Of Birth | H3: Guarantor | I3: BLOOD GROUP | J3: Relationship With Guarantor | K3: COMMENT
A4: 1 | B4: SHAHADAT HOSSAIN DIPU | D4: 25178 | E4: 01925-286832 | F4: 01905-085910 | I4: O+
A5: 2 | B5: KHADIZA | D5: 25179 | E5: 01920-854042 | F5: 01920-854042 | G5: 23/10/2004
A6: 3
A7: 4 | B7: MD ABDUL MANNAN | D7: 25186 | E7: 01914-878400 | F7: 01916-042621 | G7: 14/06/1987 | I7: A-
A8: 5 | B8: MD NAYMUL ISLAM | D8: 25187 | E8: 01827-820017 | F8: 01827-820017 | G8: 19/07/2007 | I8: A+
A9: 6 | B9: RAMIM AKTER | D9: 25188 | E9: 01742-740084 | F9: 01344-403427 | G9: 36351 | I9: O+
A10: 7 | B10: MD NOBIN | D10: 25180 | E10: 01886-685229 | F10: 01629-165254 | G10: 19/11/2006
A11: 8 | B11: MD SHAWON | D11: 25189 | E11: 01400-990381 | F11: 01712-870750 | G11: 36225 | I11: AB+
A12: 9 | B12: ABDULLAH AL SAJIB | D12: 25190 | E12: 01836-645626 | G12: 35431 | I12: B+
A13: 10 | B13: MD EMON | D13: 25193 | E13: 01818-086458 | F13: 01621-088691 | G13: 37538 | I13: O-
A14: 11 | B14: KOUSIK MITRA | D14: 25128 | E14: 0130-5498009 | F14: 01712-741310 | G14: 38904 | I14: B+
A15: 12 | B15: MD FARDIN | D15: 25192 | E15: 01862-113786 | G15: 38089
A16: 13 | B16: SIAM AHMED AZIM | D16: 25191 | E16: 01731-843407 | F16: 01968-420819 | G16: 26/08/2005 | I16: AB+
A17: 14 | B17: ISHAQUE JAHAN SAIKAT | D17: 25185 | E17: 01629-802488 | F17: 01830-938388 | G17: 31/12/1999 | I17: B+
A18: 15 | B18: NAOMI KABIR | D18: 25218 | E18: 01627-330756 | F18: 01727-798779 | G18: 18/11/2004 | I18: A+
A19: 16
A20: 17
A21: 18
A22: 19

Sheet MASSIVE 25K
A1: MASSIVE 25K দুপুর ৩টা থেকে ৫টা (রবি, মঙ্গল, বৃহস্পতি)
A2: Course Duration: 21/10/25- 21/05/26 | F2: Course Status : COMPLETE
A3: SL NO. | B3: Student ID | C3: Student Name | D3: Mobile Number | E3: Guardian Number | F3: Date Of Birth | G3: BLOOD GROUP | H3: Guarantor | I3: Relationship With Guarantor | J3: COMMENT
A4: 1 | B4: 25197 | C4: Rabbi Mia | D4: 01860-526566 | E4: 01766-078688 | F4: 38852
A5: 2 | B5: 25199 | C5: Julian Leon Baroi | D5: 01533-931417 | E5: 01756-866761/0137281719 | F5: 38574 | G5: B+
A6: 3 | B6: 25200 | C6: Md Kashfim Dewan | D6: 01956-397723 | E6: 01733-509688 | F6: 38935 | G6: AB+
A7: 4 | B7: 25205 | C7: Imtiaz Ahamed | D7: 01312-363631 | E7: 01540-110836 | F7: 37805 | G7: O+
A8: 5 | B8: 25206 | C8: Dip Roy | D8: 01749-387312 | E8: 01983-467220 | F8: 39387
A9: 6 | B9: 25207 | C9: Amitosh Mondal | D9: 01707-647084 | F9: 34618 | G9: AB+
A10: 7 | B10: 25208 | C10: Mst Anika | D10: 01779-063625 | E10: 01623-828327 | F10: 37982 | G10: O+
A11: 8 | B11: 25209 | C11: Md Tuhin Sarkar | D11: 01825-954506 | E11: 01571-028361 | F11: 37622
A12: 9 | B12: 25210 | C12: Rubaya Sultana Rumana | D12: 01760-877543 | E12: 01733-716077 | F12: 36838 | G12: B+
A13: 10 | B13: 25211 | C13: Md Easin Sonnamat | D13: 019925-59028 | E13: 01718-054018 | F13: 39114
A14: 11 | B14: 25212 | C14: Foysal Ahmed | D14: 01766-952913 | E14: 01727-963314 | F14: 38069
A15: 12 | B15: 25213 | C15: Md Tanvir Bhuiyan | D15: 01783-373127 | E15: 01813-607411 | F15: 39037 | G15: O+
A16: 13 | B16: 25214 | C16: Salma Akter | D16: 01951-640366 | E16: 01718-309320 | F16: 38247 | G16: B+
A17: 14 | B17: 25215 | C17: Angon Sarkar | D17: 01530-074774 | E17: 01988-164878 | F17: 39142 | G17: A+
A18: 15 | B18: 25216 | C18: Yead Hasan | D18: 01306-427452 | E18: 01915-8449778 | F18: 37897 | G18: O+
A19: 16 | B19: 25217 | C19: Md Easin | D19: 01717-941739 | F19: 38710 | G19: B+
A20: 17 | B20: 25230 | C20: Sadia Islam | D20: 01876-519488 | E20: 01727-749966 | F20: 39761 | G20: A+
A21: 18 | B21: 25231 | C21: Boishakhi Akter | D21: 01969-023576 | E21: 01772-298186 | F21: 39492 | G21: A+
A22: 19
A23: 20

Sheet MJLI-12
A1: MJLI-12 সকাল ১২টা থেকে ২টা (রবি, মঙ্গল, বৃহস্পতি)
A2: Course Duration: 25/11/25- 25/04/26 | F2: Course Status : COMPLETE
A3: SL NO. | B3: Student ID | C3: Student NAME | D3: Mobile Number | E3: Guardian Number | F3: Date Of Birth | G3: BLOOD GROUP | H3: Relationship With Guarantor | I3: COMMENT
A4: 1 | B4: 25221 | C4: MD ASHRAFUL | D4: 01787-108095 | E4: 01787-108095 | F4: 38888 | G4: A+
A5: 3 | B5: 25226 | C5: AYON SAHA | D5: 01647-148607 | E5: 01725-770875 | F5: 38492 | G5: A+
A6: 4 | B6: 25228 | C6: MORSALIN SHEIKH | D6: 01328-237431 | E6: 01595-057239 | F6: 39084 | G6: A+
A7: 5 | B7: 25229 | C7: RIFAT HOSSEN | D7: 01735-472206 | E7: 01724-778279 | F7: 37742 | G7: O+
A8: 6 | B8: 25181 | C8: MD JUNAYED HOSSAIN OMI | D8: 01302-601415 | E8: 01302-601415 | F8: 24/01/2007 | G8: B+
A9: 7 | B9: 26244 | C9: SUMAIYA ISLAM | D9: 01904-289237 | E9: 01820-118616 | F9: 35878 | G9: B+
A10: 8 | B10: 25198 | C10: Mohammad Abdullah | D10: 01606-588070 | F10: 36312 | G10: O+
A11: 9 | B11: 25184 | C11: RAYHAN MIAH | D11: 01568-531847 | E11: 01581-860242 | F11: 37751 | G11: A+
A12: 10 | B12: 25161 | C12: KAWSHAR HASAN SUMIT | D12: 01300-774779 | E12: 01778-226707 | F12: 24/04/2004 | G12: B+
A13: 11 | B13: 25235 | C13: JANNATUL FERDOUS AHONA | D13: 01629-427117 | E13: 01676-474979 | F13: 39390 | G13: o-
A14: 12 | B14: 25236 | C14: BIDHAN CHANDRA MONDAL | D14: 01817-470730 | E14: 01865-728884 | F14: 34554 | G14: A+
A15: 13
A16: 14
A17: 15
A18: 16
C40: MEHEDI HASSAN | D40: MD ASHRAFUL | E40: TAMANNA AKTER | F40: MD ASRAF HOSSAIN | G40: MD SOWAYEED SAWBAN | H40: MD SAJIB SARKER | I40: AYON SAHA | J40: WAS KURONI HAQUE NIPU | K40: MORSALIN SHEIKH | L40: RIFAT HOSSEN

Sheet MJLI-13
A1: MJLI-13 সকাল ১০টা থেকে ১২টা (শনি- সোম- বুধ)
A2: Course Duration: 05/01/26- 05/05/26 | F2: Course Status : CLOSEED
A3: SL NO. | B3: STUDENT ID | C3: Student NAME | D3: Mobile Number | E3: Guardian Number | F3: Date Of Birth | G3: BLOOD GROUP | H3: Relationship With Guarantor | I3: COMMENT
A4: 1 | B4: 25232 | C4: TONMOY DAS | D4: 01877-814141 | E4: 01760-592788 | F4: 38357 | G4: AB+
A5: 2 | B5: 25233 | C5: SHOVO DAS | D5: 01781-847450 | E5: 01722-006745 | F5: 38011 | G5: O+
A6: 3 | B6: 25234 | C6: MD NOMAN | D6: 01404-938126 | E6: 01991-573706 | F6: 37335 | G6: A+
A7: 4 | B7: 25237 | C7: SIFAT | D7: 01307-717082 | E7: 01611-953126 | F7: 38659 | G7: AB+
A8: 5 | B8: 25238 | C8: ROSNI AKTER | D8: 01996-412874 | E8: 01796-579940 | F8: 39566 | G8: O+
A9: 6 | B9: 25198 | C9: Mohammad Abdullah | D9: 01606-588070 | F9: 36312 | G9: O+
A10: 7 | B10: 25222 | C10: TAMANNA AKTER | D10: 01825-102613 | E10: 01928-384029 | F10: 36940 | G10: B+
A11: 8 | B11: 25227 | C11: WAS KURONI HAQUE NIPU | D11: 01902-818391 | E11: 01978-316040 | F11: 38917 | G11: B+
A12: 9 | C12: IRFAN AHMED GOUROB | D12: 01404-663420 | E12: 01955-802900 | F12: 37523 | G12: A+
A13: 10 | C13: MD RASHEDUL ISLAM | D13: 01821-665275 | E13: 01916-569053 | F13: 35095 | G13: A+
A14: 11
A15: 12
A16: 13
A17: 14
A18: 15
A19: 16
A20: 17
A21: 18

Sheet MJLI 14
A2: MJLI-14 দুপুর ৩টা থেকে ৫টা(শনি- সোম- বুধ)
A3: Course Duration 09/02/2026-09/06/2026 | F3: Course Status : complete
A4: SL NO. | B4: Student Name | C4: Student ID | D4: Mobile Number | E4: Guardian Number | F4: Date Of Birth | G4: Guarantor | H4: BLOOD GROUP | I4: COMMENT
A5: 1 | B5: Sinthea | C5: 26245 | D5: 01717-391918 | E5: 01631-798461 | F5: 24/03/2008
A6: 2 | B6: Jannatul Islam Hridika | C6: 26242 | D6: 01973-298060 | E6: 01708-186362 | F6: 37714
A7: 3 | B7: MD NOMAN | C7: 25234 | D7: 01404-938126 | E7: 01991-573706 | F7: 37335 | H7: A+
A8: 4 | B8: Rokibul Islam | C8: 26241 | D8: 01818-927715 | E8: 01836-135671 | F8: 34700
A9: 5 | B9: Fahim Islam Rahim | C9: 26243 | D9: 01934-229461 | E9: 01740-633208 | F9: 37683
A10: 7 | B10: Jannatul Ferdusi Sima | C10: 26247 | D10: 01568-351073 | E10: 01746-657901 | F10: 37633
A11: 8 | B11: Meherab Hossain | C11: 26248 | D11: 01768-211968 | E11: 01721-407081 | F11: 21/12/2005
A12: 9 | B12: Amit Ghosh | C12: 26246 | D12: 01963-605906 | E12: 01771-623676 | F12: 38118
A13: 10 | B13: MD. Shamim Sheikh | C13: 26250 | D13: 01930-045973 | E13: 01951-142528 | F13: 18/1/2000
A14: 11 | B14: UMAIZA AKTER | C14: 26240 | E14: 01799-300800
A15: 12 | B15: AKIB | C15: 26279 | D15: 01919-807785
A16: 13 | B16: MD SAJIB SARKER | C16: 25225 | D16: 01614-913087 | E16: 01401-646581 | F16: 21/12/2003 | H16: A+
A17: 14 | B17: WAS KURONI HAQUE NIPU | C17: 25227 | D17: 01902-818391 | E17: 01978-316040 | F17: 38917 | H17: B+
A18: 15 | B18: TAMANNA AKTER | C18: 25222 | D18: 01825-102613 | E18: 01928-384029 | F18: 36940 | H18: B+
A19: 16 | B19: ROSNI AKTER | C19: 25238 | D19: 01996-412874 | E19: 01796-579940 | F19: 39566 | H19: O+
A20: 17 | B20: SIFAT | C20: 25237 | D20: 01307-717082 | E20: 01611-953126 | F20: 38659 | H20: AB+
A21: 18 | B21: HASAN SHEIKH | C21: 26302 | D21: 01612-178884 | E21: 01937-891048 | F21: 36652 | H21: B+
A22: 19 | B22: MD. JISAN | C22: 26311 | D22: 01613-352953
A23: 20
A24: 21
A25: 22
A26: 23

Sheet MJLI 15
A1: MJLI15 সকাল ১০টা থেকে ১২টা (রবি, মঙ্গল, বৃহস্পতি)
A2: (🟢ACTIVE)/(🟡NOT ACTIVE)/(🔵IRREGULAR) (🟣TOP)
A3: Course Duration 12/04/2026-12/10/2026 | F3: Course Status : RUNNING
A4: SL NO. | B4: Student Name | C4: Student ID | D4: Mobile Number | E4: Guardian Number | F4: Date Of Birth | G4: Guarantor | H4: BLOOD GROUP | I4: COMMENT
A5: 1 | B5: ISTIAK AHMED🟢 | C5: 26266 | D5: 01782-577082 | E5: 01715-423779 | F5: 36203 | G5: FATHER | H5: B+
A6: 2 | B6: MD RAYHAN MIA🟢 | C6: 26257 | D6: 014096-35121 | E6: 01985-522368 | F6: 31/12/2000 | G6: FATHER
A7: 3 | B7: ARIF HOSSAIN MUNNA🟢 | C7: 26258 | D7: 01966-221626 | E7: 01752-108800 | F7: 25/2/2006 | G7: MAMA
A8: 4 | B8: SANJIDA KHAN SHUCHI🟢 | C8: 26273 | D8: 01337-341963 | E8: 01720-259100 | F8: 38760 | G8: FATHER | H8: O-
A9: 5 | B9: AKASH KHAN 🟡 | C9: 26259 | D9: 01705-198149 | E9: 01710-085632 | F9: 37692 | G9: FATHER | H9: B+
A10: 6 | B10: MAHADI HASAN🟢 | C10: 26274 | D10: 01570-237176 | E10: 01533-608018 | F10: 19/2/2007 | G10: FATHER | H10: B+
A11: 7 | B11: URMI AKTER🔵 | C11: 26261 | D11: 01753-649532 | E11: 01796-101256 | F11: 15/1/2001 | G11: FATHER | H11: A+
A12: 8 | B12: TUSHAR BHUIYAN🟡 | C12: 26262 | D12: 01938-366068 | E12: 01642-420850 | F12: 25/1/2001 | G12: BROTHER | H12: AB+
A13: 9 | B13: ATIKUR RAHMAN SINHAT🔵 | C13: 26263 | D13: 01842-535513 | E13: 01910-441518 | F13: 40033 | G13: FATHER
A14: 10 | B14: AMIMUL EHASAN🟡 | C14: 26276 | D14: 01906-828007 | E14: 01777-809997 | F14: 36444 | G14: FATHER | H14: B+
A15: 11 | B15: LAMIA UMMA SADIA🟣 | C15: 26277 | D15: 01636-660963 | E15: 01537-337270 | F15: 27/10/2004 | H15: B+
A16: 12 | B16: MD SUMON HOSSAIN🟢 | C16: 26239 | D16: 01608-068552 | E16: 01717-245534 | F16: 36444
A17: 13 | B17: SAIMUR RAHMAN SIAM🟣 | C17: 26251 | D17: 01892-738541
A18: 14 | B18: WAHIDUL ISLAM SAFAYET🟡 | C18: 26322 | D18: 01720-653079 | E18: 01794-162506 | F18: 30/3/2005 | G18: MOTHER | H18: O+
A19: 15 | B19: GOPAL NAG🟣 | C19: 26272 | D19: 01841-909597 | F19: 37814 | H19: A-
A20: 16 | B20: MUNNA MD NASER AHMED🟣 | C20: 26319 | D20: 01793-246555 | E20: 01713-004889 | F20: 31/12/1994 | G20: FATHER | H20: B+

Sheet N4-26A
A1: MASSIVE N4 MORNING BATCH (১২ টা থেকে ২ টা শনি - সোম - বুধ)
A2: Course Duration: 4/4/2026-4/8/2026 | F2: Course Status : complete
A3: SL NO. | B3: Student Name | C3: Student ID | D3: Mobile Number | E3: Guardian Number | F3: Date Of Birth | G3: Guarantor | H3: BLOOD GROUP | I3: COMMENT
A4: 1 | B4: MD TAWHID | C4: 26249 | D4: 01643-873866 | F4: 38602 | H4: O+
A5: 2 | B5: MD TOUFIK AHMED | C5: 25147 | D5: 01339-633559 | E5: 01675-551262 | F5: 26/09/2004 | H5: AB+
A6: 3 | B6: MUSFIQUR MAHMUD | C6: 25162 | D6: 01788-444277 | E6: 01818-459512 | F6: 39727 | H6: AB+
A7: 4 | B7: SIAM DEWAN | C7: 25156 | D7: 01866-449803 | F7: 26/08/2007
A8: 5 | B8: ANAMUL HASAN SABBIR | C8: 25159 | D8: 01828-023752 | E8: 01843-168007 | F8: 25/04/2005 | H8: O+
A9: 6 | B9: MD JUBAER HOSSAIN | C9: 25171 | D9: 01978-705578 | E9: 01715-050334 | F9: 39060 | H9: A+
A10: 7 | B10: MD.IKHTIYAR HOSEN | C10: 223 | D10: 01609-731308 | F10: 36623
A11: 8 | B11: AL JUBAIR | C11: 25153 | D11: 01873-652079 | E11: 01823-417527 | F11: 37408 | H11: O+
A12: 9 | B12: Tamim Visty | C12: 199 | D12: 01810-514924
A13: 10
A14: 11
A15: 12
A16: 13
A17: 14
A18: 15
A19: 16

Sheet N4-26B
A1: MASSIVE N4-26B ৪টা থেকে ৬টা (রবি, মঙ্গল, বৃহস্পতি)
A2: Course Duration 17/5/2026-17/9/2026 | G2: Course Status : COMPLETE
A3: SL NO. | B3: Student Name | C3: PAYMENT | D3: Student ID | E3: Mobile Number | F3: Guardian Number | G3: Date Of Birth | H3: Guarantor | I3: BLOOD GROUP | J3: COMMENT
A4: 1 | B4: HASIBUL ALOM RAPTY | C4: OK | D4: 25201
A5: 2 | B5: SALMA AKTER | C5: OK | D5: 25214 | E5: 01951-640366 | F5: 01718-309320 | G5: 38247 | I5: B+
A6: 3 | B6: DIP ROY | D6: 25206 | E6: 01749-387312 | F6: 01983-467220 | G6: 39387
A7: 4 | B7: RABBY MIA | C7: 5000 | D7: 25197 | E7: 01860-526566 | F7: 01766-078688 | G7: 38852
A8: 5 | B8: NUSHRAT | D8: 25173
A9: 6 | B9: FAYSAL AHMED | D9: 25212 | E9: 01766-952913 | F9: 01727-963314 | G9: 38069
A10: 7 | B10: SADIA ISLAM | C10: OK | D10: 25230 | E10: 01876-519488 | F10: 01799-444255 | G10: 39761 | I10: A+
A11: 8 | B11: NAHAR SHOVA | C11: OK | D11: 26296 | E11: 01730-845444
A12: 9 | B12: MD. IBRAHIM HASAN | C12: OK | D12: 26306 | E12: 01967-1130214
A13: 10 | B13: RIFAT SIKDER | C13: OK | D13: 26290 | E13: 01811-489631 | F13: 01745-669096 | G13: 28/12/2002 | I13: O+
A14: 11 | B14: JARIN MONI | D14: 25110 | E14: 01792-480988
A15: 12 | B15: NIYAZ MORSHED | D15: 173 | E15: 01816-335423
A16: 13 | B16: MD EMON | D16: 25193 | E16: 01818-086458 | F16: 01621-088691 | G16: 37538 | I16: O-
A17: 14
A18: 15
A19: 16
A20: 17
A21: 18

Sheet MJLI 16
A1: MJLI 16 ২ টা থেকে ৪ টা (শনি - সোম - বুধ )
A2: (🟢ACTIVE)/(🟡NOT ACTIVE)/(🔵IRREGULAR) (🟣TOP)
A3: Course Duration 6/5/2026-6/10/2026 | F3: Course Status : CLOSED
A4: SL | B4: Student Name | C4: Student ID | D4: Mobile Number | E4: Guardian Number | F4: Date Of Birth | G4: Guarantor | H4: BLOOD GROUP | I4: COMMENT
A5: 1 | B5: MD. RUHULLAH SEAM🟣 | C5: 26275 | D5: 01321-576072 | E5: 01945-409980 | F5: 37656 | G5: BROTHER
A6: 2 | B6: SAMIR HOSSAIN | C6: 26309 | D6: 01406-454347 | E6: 01736-218135 | F6: 23/02/2004 | G6: MOTHER | H6: B+
A7: 3 | B7: MD ALI AZGOR🟢 | C7: 26270 | D7: 01848-565827 | E7: 01676-124400 | F7: 15/02/2000 | G7: UNCLE | H7: O-
A8: 4 | B8: LUCKYI ISLAM🟡 | C8: 26271 | D8: 01792-181319 | E8: 01864-940169 | F8: 14/04/1995 | G8: BROTHER
A9: 5 | B9: MEHEDI HASSAN🔵 | C9: 26281 | D9: 01630-220771 | E9: 01712-551994 | F9: 2/4/0200 | G9: FATHER
A10: 6 | B10: TANVEER HOSSAIN ANTOR🔵 | C10: 26282 | D10: 01720-594343 | E10: 01733-151484 | F10: 38657
A11: 7 | B11: AHAD HOSSAIN KIRON🔵 | C11: 26283 | D11: 01342-375777 | E11: 01733-151484 | F11: 20/9/2006 | G11: FATHER
A12: 8 | B12: MD RAKIB VUIYA🟡 | C12: 26285 | D12: 01744-217276 | F12: 18/11/2003
A13: 9 | B13: PIPASHA ROY🟡 | C13: 26292 | D13: 01910-101993 | E13: 01816-712289 | F13: 34283 | G13: BROTHER | H13: B+
A14: 10 | B14: MOHAMMAD NAIM🟣 | C14: 26289 | D14: 01986-421576 | E14: 01646-814758 | F14: 39030 | G14: FATHER | H14: B+
A15: 11 | B15: AMINUL ISLAM JISAN🟢 | C15: 25126 | D15: 01758-034945 | E15: 0171954-0296 | F15: 38475 | G15: FATHER
A16: 12 | B16: MOHAMMAD AKASH🟢 | C16: 26284 | D16: 01778-265174 | E16: 01728-350070 | F16: 38362 | G16: MAMA | H16: O+
A17: 13 | B17: MD SELIM UDDIN🟢 | C17: 26314 | D17: 01796-409850 | E17: 01968-141906 | F17: 36529 | G17: MOTHER | H17: A+

Sheet MJLI 17
A1: MASSIVE 17 সকাল ১০টা থেকে ১২টা (শনি - সোম - বুধ )
A2: (🟢ACTIVE)/(🟡NOT ACTIVE)/(🔵IRREGULAR) (🟣TOP)
A3: Course Duration:06JUN～6 NOV | F3: Course Status : RUNNING
A4: SL NO. | B4: Student Name | C4: Student ID | D4: Mobile Number | E4: Guardian Number | F4: Date Of Birth | G4: Guarantor | H4: BLOOD GROUP | I4: COMMENT
A5: 1 | B5: SAIFUL ISLAM🟣 | C5: 26288 | D5: 01864-771046 | E5: 01703-797085 | F5: 38604 | H5: A+
A6: 2 | B6: MD HRIDOY HOSSAIN🟣 | C6: 26287 | D6: 01615-779109 | E6: 01703-797085 | F6: 38698 | H6: A+
A7: 3 | B7: RUBAYA SULTANA RUMANA | C7: 25210 | D7: 01760-877543 | E7: 01733-716077 | F7: 36749 | H7: B+
A8: 4 | B8: SAMI BIN SAIF ARAF🟢 | C8: 26295 | D8: 01572-918862 | E8: 01511-242721 | F8: 39212 | G8: MOTHER | H8: B+
A9: 5 | B9: MIM KHAN🟡 | C9: 26298 | D9: 01775-848484 | E9: 01716-025629 | F9: 14/7/1999 | G9: MOTHER | H9: A+
A10: 6 | B10: ANAS ABDULLAH🟣 | C10: 26253 | D10: 01613-380569 | F10: 38048 | G10: FATHER | H10: O+
A11: 7 | B11: PARVEZ AHAMMAD TOPU🟢 | C11: 26312 | D11: 01945-757129 | E11: 01711-303651 | F11: 24/2/2005 | G11: FATHER | H11: A+
A12: 8 | B12: ARSHAD KHAN🔵 | C12: 26300 | D12: 01627-319047 | E12: 01741-224222 | F12: 36070 | G12: FATHER
A13: 9 | B13: RASEL HALDER🟢 | C13: 26299 | D13: 01865-054738 | E13: 01865-054738 | F13: 33734 | G13: FATHER
A14: 10 | B14: MD SANJIL AHMED JIHAD🔵 | C14: 26301 | D14: 01943-006678 | E14: 01911-626870 | F14: 14/7/2004 | G14: MOTHER | H14: A+
A15: 11 | B15: ARIFA AKTER🟣 | C15: 26304 | E15: 01772-921810 | F15: 15/4/2005 | G15: MOTHER | H15: AB+
A16: 12 | B16: MD ABU SAYEED SAYMON🟢 | C16: 26313 | D16: 01836-134119 | F16: 34436 | H16: A+
A17: 13 | B17: NAZMUL HASAN MAZUMDER🟢 | C17: 26308 | D17: 01743-028108 | F17: 37624
A18: 14 | B18: MOHAMMAD ARAFAT🟢 | C18: 26307 | D18: 01775-537173 | F18: 30/7/2004
A19: 15 | B19: MD POLASH MIA🟢 | C19: 26330 | D19: 01795-819170 | E19: 01301-960655 | F19: 38809 | H19: O+
A20: 16 | B20: MD. RUHULLAH SEAM🟣 | C20: 26275 | D20: 01321-576072 | E20: 01945-409980 | F20: 37656 | G20: BROTHER
A21: 17 | B21: SAMIR HOSSAIN | C21: 26309 | D21: 01406-454347 | E21: 01736-218135 | F21: 23/02/2004 | G21: MOTHER | H21: B+
A22: 18 | B22: MD ALI AZGOR🟢 | C22: 26270 | D22: 01848-565827 | E22: 01676-124400 | F22: 15/02/2000 | G22: UNCLE | H22: O-
A23: 19 | B23: MD RAKIB VUIYA🟡 | C23: 26285 | D23: 01744-217276 | F23: 18/11/2003
A24: 20 | B24: AMINUL ISLAM JISAN🟢 | C24: 25126 | D24: 01758-034945 | E24: 0171954-0296 | F24: 38475 | G24: FATHER
A25: 21
A26: 22

Sheet MJLI 18
A1: MASSIVE 18 দুপুর ২টা থেকে ৪টা (রবি, মঙ্গল, বৃহস্পতি)
A2: (🟢ACTIVE)/(🟡NOT ACTIVE)/(🔵IRREGULAR) (🟣TOP)
A3: Course Duration 23/6/2026- 23/11/2026 | F3: Course Status : RUNNING
A4: SL NO. | B4: Student Name | C4: Student ID | D4: Mobile Number | E4: Guardian Number | F4: Date Of Birth | G4: Guarantor | H4: BLOOD GROUP | I4: COMMENT
A5: 1 | B5: SANJIDA SUMAIYA🟣 | C5: 26303 | D5: 01709-920330 | E5: 01711-171807 | F5: 35465 | G5: MOTHER | H5: AB+
A6: 2 | B6: ZIDAN HOSSAIN🟢 | C6: 26317 | D6: 01924-244874 | E6: 01945-299416 | F6: 38632 | G6: MOTHER | H6: A+
A7: 3 | B7: ABU BOKKOR ALVI | C7: 26285 | D7: 01754-977376 | E7: 01724-279502 | F7: 23/5/2005 | G7: MOTHER | H7: B+
A8: 4 | B8: MD YEASIN ARAFAT🔵 | D8: 01538-329494 | E8: 01829-439907 | F8: 38660 | H8: O+
A9: 5 | B9: POLOK SARKAR🟣 | C9: 26320 | D9: 01318-617205 | E9: 01716-795301 | F9: 39060
A10: 6 | B10: MD MIRAJ HOSSAIN MOJUMDER🟢 | C10: 26323 | D10: 01600-238747 | E10: 01811-959583 | F10: 15/3/2007 | G10: FATHER | H10: B-
A11: 7 | B11: MAISHA RAHMAN🟢 | C11: 26318 | D11: 01738-186058 | E11: 01684-54657 | F11: 38475 | G11: MOTHER | H11: AB-
A12: 8 | B12: BOISHAKHI AKTER🟢 | C12: 25231 | D12: 01969-023576 | E12: 01772-298186 | F12: 14/2/2008 | G12: FATHER | H12: A+
A13: 9 | B13: WAFA ALOM🟢 | C13: 26326 | D13: 01620-053040 | E13: 01923-417380 | F13: 38028 | H13: B+
A14: 10 | B14: AYSHA AKHTER TASNIM🟣 | C14: 26327 | D14: 01833-542804 | E14: 01679-101004 | F14: 21/11/2004 | H14: B+
A15: 11 | B15: AL MAHMUD AKTAZ🟢 | C15: 26328 | D15: 01883-666019 | E15: 01779-091020 | F15: 23/10/2005 | G15: BROTHER | H15: B+
A16: 12 | B16: SAZZAD BEPARI 🟢 | C16: 26310 | D16: 01611-491812 | E16: 01712-294147 | F16: 23/1/2005 | G16: FATHER | H16: O+
A17: 13 | B17: AYSHA AKHTER RIA🟢 | C17: 26335 | D17: 01888-678560 | E17: 01609-726987 | F17: 38231 | G17: FATHER | H17: AB+
A18: 14 | B18: MORSHALIN MAHI🔵 | C18: 26264 | D18: 01917-804949 | E18: 01714-221347 | F18: 39152 | G18: MOTHER | H18: A+
A19: 15 | B19: FAHAD HOSSAIN🟢 | C19: 26269 | D19: 01811-451717 | E19: 01811-451717 | F19: 39366 | H19: B+
A20: 16 | B20: MD. ALVI HAQUE🔵 | C20: 26324 | D20: 01706-508632 | E20: 01779-295561 | F20: 28/7/2006 | H20: A+
A21: 17 | B21: MOHAMMAD ALOM🔵 | C21: 26316 | D21: 01770-065019 | E21: 01738-205157 | F21: 39149 | G21: FATHER | H21: A+
A22: 18 | B22: LUCKYI ISLAM🟡 | C22: 26271 | D22: 01792-181319 | E22: 01864-940169 | F22: 14/04/1995 | G22: BROTHER
A23: 19 | B23: PIPASHA ROY🟡 | C23: 26292 | D23: 01910-101993 | E23: 01816-712289 | F23: 34283 | G23: BROTHER | H23: B+
A24: 20 | B24: MOHAMMAD NAIM🟣 | C24: 26289 | D24: 01986-421576 | E24: 01646-814758 | F24: 39030 | G24: FATHER | H24: B+
A25: 21 | B25: MOHAMMAD AKASH🟢 | C25: 26284 | D25: 01778-265174 | E25: 01728-350070 | F25: 38362 | G25: MAMA | H25: O+
A26: 22 | B26: MD SELIM UDDIN🟢 | C26: 26314 | D26: 01796-409850 | E26: 01968-141906 | F26: 36529 | G26: MOTHER | H26: A+

Sheet MJLI 19
A1: MASSIVE 19 সকাল ১১ঃ৪৫টা থেকে ১ঃ৪৫টা শনি - সোম - বুধ
A2: (🟢ACTIVE)/(🟡NOT ACTIVE)/(🔵IRREGULAR) (🟣TOP)
A3: Course Duration : 15/7/2026-15/12/2026 | F3: Course Status : RUNNING
A4: SL NO. | B4: Student Name | C4: Student ID | D4: Mobile Number | E4: Guardian Number | F4: Date Of Birth | G4: Guarantor | H4: BLOOD GROUP | I4: COMMENT
A5: 1 | B5: MD NUR ALOM🟢 | C5: 26325 | D5: 01747-667790 | E5: 01727-343019 | F5: 30/12/2004 | H5: AB+
A6: 2 | B6: IBRAHIM🟢 | C6: 26343 | D6: 01965-107613 | F6: 38421 | H6: O+
A7: 3 | B7: EVA🟢 | C7: 26342 | D7: 01742-860731 | F7: 31/8/2000 | H7: O+
